<?xml version="1.0"?>
<robot xmlns:xacro="http://www.ros.org/wiki/xacro" >
    <xacro:include filename="$(find urdf_description)/urdf/fishbot/common_inertia.xacro" />
    <xacro:macro name="wheel_xacro" params="wheel_name xyz">
        <!-- 机器人的wheel部件，惯性测量单元 -->
        <link name="${wheel_name}_link">
            <!-- 定义外观描述 -->
            <visual>
                <!-- 沿着自己的几何中心的偏移和旋转 -->
                <origin xyz="0 0 0" rpy="1.57079 0 0" />
                <!-- 几何形状 -->
                <geometry>
                <!-- cylinder -->
                    <cylinder radius="0.032" length="0.04" />
                </geometry>
                <!-- 定义材质和颜色 0.5半透明-->
                <material name="yellow">
                    <color rgba="1.0 1.0 0.0 0.8" />
                </material>
            </visual> 
             <collision>
                <!-- 沿着自己的几何中心的偏移和旋转 -->
                <origin xyz="0 0 0" rpy="1.57079 0 0" />
                <!-- 几何形状 -->
                <geometry>
                <!-- cylinder -->
                    <cylinder radius="0.032" length="0.04" />
                </geometry>
                <!-- 定义材质和颜色 0.5半透明-->
                <material name="yellow">
                    <color rgba="1.0 1.0 0.0 0.8" />
                </material>
            </collision>
            <xacro:cylinder_inertia m="0.05" r="0.032" h="0.04" />
        </link>

        <!-- 定义关节 -->
        <joint name="${wheel_name}_joint" type="continuous">
            <!-- 关节连接的父链接 -->
            <parent link="base_link" />
            <!-- 关节连接的子链接 -->
            <child link="${wheel_name}_link" />
            <!-- 关节的位置和旋转 -->
            <origin xyz="${xyz}" rpy="0 0 0" />
            <!-- 围绕y轴旋转 -->
            <axis xyz="0.0 1 0.0"/>
        </joint>

        <gazebo reference="${wheel_name}_link">
            <!-- <material>Gazebo/Black</material> -->
            <!-- 摩擦力 -->
            <mu1 value="20"/>
            <mu2 value="20"/>
            <kp value="1000000000.0"/>
            <kd value="1.0"/>
        </gazebo>
    </xacro:macro>
</robot>
